Traceback (most recent call last):
  File "/opt/miniconda3/envs/srh/lib/python3.10/site-packages/jupyter_cache/executors/utils.py", line 51, in single_nb_execution
    executenb(
  File "/opt/miniconda3/envs/srh/lib/python3.10/site-packages/nbclient/client.py", line 1204, in execute
    return NotebookClient(nb=nb, resources=resources, km=km, **kwargs).execute()
  File "/opt/miniconda3/envs/srh/lib/python3.10/site-packages/nbclient/util.py", line 84, in wrapped
    return just_run(coro(*args, **kwargs))
  File "/opt/miniconda3/envs/srh/lib/python3.10/site-packages/nbclient/util.py", line 62, in just_run
    return loop.run_until_complete(coro)
  File "/opt/miniconda3/envs/srh/lib/python3.10/asyncio/base_events.py", line 641, in run_until_complete
    return future.result()
  File "/opt/miniconda3/envs/srh/lib/python3.10/site-packages/nbclient/client.py", line 663, in async_execute
    await self.async_execute_cell(
  File "/opt/miniconda3/envs/srh/lib/python3.10/site-packages/nbclient/client.py", line 965, in async_execute_cell
    await self._check_raise_for_error(cell, cell_index, exec_reply)
  File "/opt/miniconda3/envs/srh/lib/python3.10/site-packages/nbclient/client.py", line 862, in _check_raise_for_error
    raise CellExecutionError.from_cell_and_msg(cell, exec_reply_content)
nbclient.exceptions.CellExecutionError: An error occurred while executing the following cell:
------------------
expected_frequencies = pd.DataFrame(
    np.outer(rows, cols) / n, index=table.index, columns=table.columns
)
------------------

[0;31m---------------------------------------------------------------------------[0m
[0;31mNameError[0m                                 Traceback (most recent call last)
Input [0;32mIn [25][0m, in [0;36m<cell line: 1>[0;34m()[0m
[1;32m      1[0m expected_frequencies [38;5;241m=[39m pd[38;5;241m.[39mDataFrame(
[0;32m----> 2[0m     np[38;5;241m.[39mouter(rows, cols) [38;5;241m/[39m n, index[38;5;241m=[39m[43mtable[49m[38;5;241m.[39mindex, columns[38;5;241m=[39mtable[38;5;241m.[39mcolumns
[1;32m      3[0m )

[0;31mNameError[0m: name 'table' is not defined
NameError: name 'table' is not defined

